Workbook
Name KategorieListe: Listen!$C$2:$C$10
Name katFilter: 'Mythen-Dashboard'!$C$8
Name klassFilter: 'Mythen-Dashboard'!$C$7
Name KlassifikationsListe: Listen!$B$2:$B$7
Name ReihenfolgeListe: Listen!$F$2:$F$3
Name selectedGroup: 'Mythen-Dashboard'!$C$6
Name sortDir: Listen!$G$3
Name sortFeld: 'Mythen-Dashboard'!$I$6
Name SortFelderListe: Listen!$D$2:$D$10
Name sortIdx: Listen!$G$2
Name sortReihen: 'Mythen-Dashboard'!$I$7
Name sucheText: 'Mythen-Dashboard'!$C$9
Name ZielgruppenListe: Listen!$A$2:$A$6

Sheet Mythen-Dashboard
A1: Cannabis: Mythen & Evidenz — Daten-Explorer für Präventionsfachkräfte
A2: Datengrundlage: drei Befragungspanels — Volljährige (18–70, n=2.079) und Minderjährige (16–17, n=555), beide gewichtet, sowie Konsumierende (n=143, Anbauvereinigungen, ungewichtet). CaRM, ISD Hamburg, Sommer 2025.
A3: ⚠ WICHTIG — Keine Nachrechnung möglich: Die Werte sind methodisch standardisiert (0–100 Punkte) und für Volljährige/Minderjährige gewichtet. Eine eigenständige Nachrechnung anhand dieser Zahlen ist nicht möglich, da zu viele Zwischenschritte fehlen. Vollständige Erläuterungen → Tab „Erläuterungen“.
A5: FILTER UND SUCHE | F5: SORTIEREN UND ÜBERBLICK
B6: Zielgruppe | C6: Erwachsene (18–70) | G6: Sortieren nach | I6: Mythos-Nr.
B7: Klassifikation | C7: Alle | G7: Reihenfolge | I7: Aufsteigend
B8: Kategorie | C8: Alle | G8: Treffer | I8: =SUM(Live!$M$2:$M$43) & " von 42 Mythen" -> 42 von 42 Mythen
B9: Suche in "Mythos"
A11: Kürzeste Lesehilfe: Klassifikation farbcodiert (grün = richtig → rot = falsch). Kenntnis = % der Zielgruppe; übrige Spalten = standardisierte Punkte 0–100 (höher = stärker). Vollständige Erläuterungen → Tab „Erläuterungen“.
A13: Nr. | B13: Mythos | C13: Kategorie | D13: Klassifikation | E13: Kenntnis % | F13: Bedeutung Punkte | G13: Richtigkeit Punkte | H13: Präv.-Bedeutung Punkte | I13: Bevölk.-Relevanz Punkte | J13: Faktenkarte
A14: =IFERROR(INDEX(Live!$A$2:$A$43,MATCH(1,Live!$P$2:$P$43,0)),"") -> 1 | B14: =IFERROR(INDEX(Live!$B$2:$B$43,MATCH(1,Live!$P$2:$P$43,0)),"") -> Cannabis ist ein Allheilmittel. | C14: =IFERROR(INDEX(Live!$C$2:$C$43,MATCH(1,Live!$P$2:$P$43,0)),"") -> Medizinischer und therapeutischer Nutzen | D14: =IFERROR(INDEX(Live!$D$2:$D$43,MATCH(1,Live!$P$2:$P$43,0)),"") -> Falsch | E14: =IFERROR(INDEX(Live!$E$2:$E$43,MATCH(1,Live!$P$2:$P$43,0)),"") -> 12.32 | F14: =IFERROR(INDEX(Live!$F$2:$F$43,MATCH(1,Live!$P$2:$P$43,0)),"") -> 52.82 | G14: =IFERROR(INDEX(Live!$G$2:$G$43,MATCH(1,Live!$P$2:$P$43,0)),"") -> 49.1 | H14: =IFERROR(INDEX(Live!$H$2:$H$43,MATCH(1,Live!$P$2:$P$43,0)),"") -> 41.49 | I14: =IFERROR(INDEX(Live!$I$2:$I$43,MATCH(1,Live!$P$2:$P$43,0)),"") -> 5.6 | J14: =IFERROR(HYPERLINK(VLOOKUP($A14,Mythen!$A$3:$F$44,6,FALSE()),"Faktenkarte öffnen ↗"),"") -> Faktenkarte öffnen ↗
A15: =IFERROR(INDEX(Live!$A$2:$A$43,MATCH(2,Live!$P$2:$P$43,0)),"") -> 2 | B15: =IFERROR(INDEX(Live!$B$2:$B$43,MATCH(2,Live!$P$2:$P$43,0)),"") -> Cannabiskonsum ist harmlos. | C15: =IFERROR(INDEX(Live!$C$2:$C$43,MATCH(2,Live!$P$2:$P$43,0)),"") -> Allgemeine Einschätzung der Gefährlichkeit | D15: =IFERROR(INDEX(Live!$D$2:$D$43,MATCH(2,Live!$P$2:$P$43,0)),"") -> Falsch | E15: =IFERROR(INDEX(Live!$E$2:$E$43,MATCH(2,Live!$P$2:$P$43,0)),"") -> 18.02 | F15: =IFERROR(INDEX(Live!$F$2:$F$43,MATCH(2,Live!$P$2:$P$43,0)),"") -> 52.63 | G15: =IFERROR(INDEX(Live!$G$2:$G$43,MATCH(2,Live!$P$2:$P$43,0)),"") -> 63.77 | H15: =IFERROR(INDEX(Live!$H$2:$H$43,MATCH(2,Live!$P$2:$P$43,0)),"") -> 31.78 | I15: =IFERROR(INDEX(Live!$I$2:$I$43,MATCH(2,Live!$P$2:$P$43,0)),"") -> 6.5 | J15: =IFERROR(HYPERLINK(VLOOKUP($A15,Mythen!$A$3:$F$44,6,FALSE()),"Faktenkarte öffnen ↗"),"") -> Faktenkarte öffnen ↗
A16: =IFERROR(INDEX(Live!$A$2:$A$43,MATCH(3,Live!$P$2:$P$43,0)),"") -> 3 | B16: =IFERROR(INDEX(Live!$B$2:$B$43,MATCH(3,Live!$P$2:$P$43,0)),"") -> Cannabiskonsum durch Heranwachsende führt in stärkerem Maße als bei Erwachsenen zu gesundheitlichen Schäden. | C16: =IFERROR(INDEX(Live!$C$2:$C$43,MATCH(3,Live!$P$2:$P$43,0)),"") -> Allgemeine Einschätzung der Gefährlichkeit | D16: =IFERROR(INDEX(Live!$D$2:$D$43,MATCH(3,Live!$P$2:$P$43,0)),"") -> Eher richtig | E16: =IFERROR(INDEX(Live!$E$2:$E$43,MATCH(3,Live!$P$2:$P$43,0)),"") -> 48.64 | F16: =IFERROR(INDEX(Live!$F$2:$F$43,MATCH(3,Live!$P$2:$P$43,0)),"") -> 76.78 | G16: =IFERROR(INDEX(Live!$G$2:$G$43,MATCH(3,Live!$P$2:$P$43,0)),"") -> 77.93 | H16: =IFERROR(INDEX(Live!$H$2:$H$43,MATCH(3,Live!$P$2:$P$43,0)),"") -> 30.43 | I16: =IFERROR(INDEX(Live!$I$2:$I$43,MATCH(3,Live!$P$2:$P$43,0)),"") -> 16.9 | J16: =IFERROR(HYPERLINK(VLOOKUP($A16,Mythen!$A$3:$F$44,6,FALSE()),"Faktenkarte öffnen ↗"),"") -> Faktenkarte öffnen ↗
A17: =IFERROR(INDEX(Live!$A$2:$A$43,MATCH(4,Live!$P$2:$P$43,0)),"") -> 4 | B17: =IFERROR(INDEX(Live!$B$2:$B$43,MATCH(4,Live!$P$2:$P$43,0)),"") -> Cannabis ist weniger schädlich als Alkohol. | C17: =IFERROR(INDEX(Live!$C$2:$C$43,MATCH(4,Live!$P$2:$P$43,0)),"") -> Allgemeine Einschätzung der Gefährlichkeit | D17: =IFERROR(INDEX(Live!$D$2:$D$43,MATCH(4,Live!$P$2:$P$43,0)),"") -> Richtig | E17: =IFERROR(INDEX(Live!$E$2:$E$43,MATCH(4,Live!$P$2:$P$43,0)),"") -> 35.16 | F17: =IFERROR(INDEX(Live!$F$2:$F$43,MATCH(4,Live!$P$2:$P$43,0)),"") -> 62.1 | G17: =IFERROR(INDEX(Live!$G$2:$G$43,MATCH(4,Live!$P$2:$P$43,0)),"") -> 69.66 | H17: =IFERROR(INDEX(Live!$H$2:$H$43,MATCH(4,Live!$P$2:$P$43,0)),"") -> 27.37 | I17: =IFERROR(INDEX(Live!$I$2:$I$43,MATCH(4,Live!$P$2:$P$43,0)),"") -> 11.2 | J17: =IFERROR(HYPERLINK(VLOOKUP($A17,Mythen!$A$3:$F$44,6,FALSE()),"Faktenkarte öffnen ↗"),"") -> Faktenkarte öffnen ↗
A18: =IFERROR(INDEX(Live!$A$2:$A$43,MATCH(5,Live!$P$2:$P$43,0)),"") -> 5 | B18: =IFERROR(INDEX(Live!$B$2:$B$43,MATCH(5,Live!$P$2:$P$43,0)),"") -> Cannabis ist schwierig zu dosieren. | C18: =IFERROR(INDEX(Live!$C$2:$C$43,MATCH(5,Live!$P$2:$P$43,0)),"") -> Risiken durch Dosierung und Qualität | D18: =IFERROR(INDEX(Live!$D$2:$D$43,MATCH(5,Live!$P$2:$P$43,0)),"") -> Richtig | E18: =IFERROR(INDEX(Live!$E$2:$E$43,MATCH(5,Live!$P$2:$P$43,0)),"") -> 16.33 | F18: =IFERROR(INDEX(Live!$F$2:$F$43,MATCH(5,Live!$P$2:$P$43,0)),"") -> 68.51 | G18: =IFERROR(INDEX(Live!$G$2:$G$43,MATCH(5,Live!$P$2:$P$43,0)),"") -> 76.43 | H18: =IFERROR(INDEX(Live!$H$2:$H$43,MATCH(5,Live!$P$2:$P$43,0)),"") -> 26.37 | I18: =IFERROR(INDEX(Live!$I$2:$I$43,MATCH(5,Live!$P$2:$P$43,0)),"") -> 5.1 | J18: =IFERROR(HYPERLINK(VLOOKUP($A18,Mythen!$A$3:$F$44,6,FALSE()),"Faktenkarte öffnen ↗"),"") -> Faktenkarte öffnen ↗
A19: =IFERROR(INDEX(Live!$A$2:$A$43,MATCH(6,Live!$P$2:$P$43,0)),"") -> 6 | B19: =IFERROR(INDEX(Live!$B$2:$B$43,MATCH(6,Live!$P$2:$P$43,0)),"") -> Mischkonsum von Cannabis mit anderen Substanzen ist besonders risikoreich. | C19: =IFERROR(INDEX(Live!$C$2:$C$43,MATCH(6,Live!$P$2:$P$43,0)),"") -> Risiken durch Dosierung und Qualität | D19: =IFERROR(INDEX(Live!$D$2:$D$43,MATCH(6,Live!$P$2:$P$43,0)),"") -> Richtig | E19: =IFERROR(INDEX(Live!$E$2:$E$43,MATCH(6,Live!$P$2:$P$43,0)),"") -> 43.75 | F19: =IFERROR(INDEX(Live!$F$2:$F$43,MATCH(6,Live!$P$2:$P$43,0)),"") -> 77.02 | G19: =IFERROR(INDEX(Live!$G$2:$G$43,MATCH(6,Live!$P$2:$P$43,0)),"") -> 88.97 | H19: =IFERROR(INDEX(Live!$H$2:$H$43,MATCH(6,Live!$P$2:$P$43,0)),"") -> 21.93 | I19: =IFERROR(INDEX(Live!$I$2:$I$43,MATCH(6,Live!$P$2:$P$43,0)),"") -> 11.7 | J19: =IFERROR(HYPERLINK(VLOOKUP($A19,Mythen!$A$3:$F$44,6,FALSE()),"Faktenkarte öffnen ↗"),"") -> Faktenkarte öffnen ↗
A20: =IFERROR(INDEX(Live!$A$2:$A$43,MATCH(7,Live!$P$2:$P$43,0)),"") -> 7 | B20: =IFERROR(INDEX(Live!$B$2:$B$43,MATCH(7,Live!$P$2:$P$43,0)),"") -> Zusätze im Cannabis führen zu erhöhten Gesundheitsrisiken. | C20: =IFERROR(INDEX(Live!$C$2:$C$43,MATCH(7,Live!$P$2:$P$43,0)),"") -> Risiken durch Dosierung und Qualität | D20: =IFERROR(INDEX(Live!$D$2:$D$43,MATCH(7,Live!$P$2:$P$43,0)),"") -> Richtig | E20: =IFERROR(INDEX(Live!$E$2:$E$43,MATCH(7,Live!$P$2:$P$43,0)),"") -> 35.06 | F20: =IFERROR(INDEX(Live!$F$2:$F$43,MATCH(7,Live!$P$2:$P$43,0)),"") -> 76.49 | G20: =IFERROR(INDEX(Live!$G$2:$G$43,MATCH(7,Live!$P$2:$P$43,0)),"") -> 85.7 | H20: =IFERROR(INDEX(Live!$H$2:$H$43,MATCH(7,Live!$P$2:$P$43,0)),"") -> 24.05 | I20: =IFERROR(INDEX(Live!$I$2:$I$43,MATCH(7,Live!$P$2:$P$43,0)),"") -> 10.1 | J20: =IFERROR(HYPERLINK(VLOOKUP($A20,Mythen!$A$3:$F$44,6,FALSE()),"Faktenkarte öffnen ↗"),"") -> Faktenkarte öffnen ↗
A21: =IFERROR(INDEX(Live!$A$2:$A$43,MATCH(8,Live!$P$2:$P$43,0)),"") -> 8 | B21: =IFERROR(INDEX(Live!$B$2:$B$43,MATCH(8,Live!$P$2:$P$43,0)),"") -> Cannabiskonsum schädigt den Fötus. | C21: =IFERROR(INDEX(Live!$C$2:$C$43,MATCH(8,Live!$P$2:$P$43,0)),"") -> Risiken für den Körper und die Entwicklung | D21: =IFERROR(INDEX(Live!$D$2:$D$43,MATCH(8,Live!$P$2:$P$43,0)),"") -> Richtig | E21: =IFERROR(INDEX(Live!$E$2:$E$43,MATCH(8,Live!$P$2:$P$43,0)),"") -> 42.35 | F21: =IFERROR(INDEX(Live!$F$2:$F$43,MATCH(8,Live!$P$2:$P$43,0)),"") -> 76.49 | G21: =IFERROR(INDEX(Live!$G$2:$G$43,MATCH(8,Live!$P$2:$P$43,0)),"") -> 89.87 | H21: =IFERROR(INDEX(Live!$H$2:$H$43,MATCH(8,Live!$P$2:$P$43,0)),"") -> 21.16 | I21: =IFERROR(INDEX(Live!$I$2:$I$43,MATCH(8,Live!$P$2:$P$43,0)),"") -> 11 | J21: =IFERROR(HYPERLINK(VLOOKUP($A21,Mythen!$A$3:$F$44,6,FALSE()),"Faktenkarte öffnen ↗"),"") -> Faktenkarte öffnen ↗
A22: =IFERROR(INDEX(Live!$A$2:$A$43,MATCH(9,Live!$P$2:$P$43,0)),"") -> 9 | B22: =IFERROR(INDEX(Live!$B$2:$B$43,MATCH(9,Live!$P$2:$P$43,0)),"") -> Eine Überdosierung von Cannabis führt nicht zum Tod. | C22: =IFERROR(INDEX(Live!$C$2:$C$43,MATCH(9,Live!$P$2:$P$43,0)),"") -> Risiken durch Dosierung und Qualität | D22: =IFERROR(INDEX(Live!$D$2:$D$43,MATCH(9,Live!$P$2:$P$43,0)),"") -> Richtig | E22: =IFERROR(INDEX(Live!$E$2:$E$43,MATCH(9,Live!$P$2:$P$43,0)),"") -> 20.71 | F22: =IFERROR(INDEX(Live!$F$2:$F$43,MATCH(9,Live!$P$2:$P$43,0)),"") -> 66.53 | G22: =IFERROR(INDEX(Live!$G$2:$G$43,MATCH(9,Live!$P$2:$P$43,0)),"") -> 74.3 | H22: =IFERROR(INDEX(Live!$H$2:$H$43,MATCH(9,Live!$P$2:$P$43,0)),"") -> 27.58 | I22: =IFERROR(INDEX(Live!$I$2:$I$43,MATCH(9,Live!$P$2:$P$43,0)),"") -> 6.6 | J22: =IFERROR(HYPERLINK(VLOOKUP($A22,Mythen!$A$3:$F$44,6,FALSE()),"Faktenkarte öffnen ↗"),"") -> Faktenkarte öffnen ↗
A23: =IFERROR(INDEX(Live!$A$2:$A$43,MATCH(10,Live!$P$2:$P$43,0)),"") -> 10 | B23: =IFERROR(INDEX(Live!$B$2:$B$43,MATCH(10,Live!$P$2:$P$43,0)),"") -> Cannabis wirkt gegen Schmerzen. | C23: =IFERROR(INDEX(Live!$C$2:$C$43,MATCH(10,Live!$P$2:$P$43,0)),"") -> Medizinischer und therapeutischer Nutzen | D23: =IFERROR(INDEX(Live!$D$2:$D$43,MATCH(10,Live!$P$2:$P$43,0)),"") -> Eher falsch | E23: =IFERROR(INDEX(Live!$E$2:$E$43,MATCH(10,Live!$P$2:$P$43,0)),"") -> 68.28 | F23: =IFERROR(INDEX(Live!$F$2:$F$43,MATCH(10,Live!$P$2:$P$43,0)),"") -> 70.26 | G23: =IFERROR(INDEX(Live!$G$2:$G$43,MATCH(10,Live!$P$2:$P$43,0)),"") -> 49.74 | H23: =IFERROR(INDEX(Live!$H$2:$H$43,MATCH(10,Live!$P$2:$P$43,0)),"") -> 46.58 | I23: =IFERROR(INDEX(Live!$I$2:$I$43,MATCH(10,Live!$P$2:$P$43,0)),"") -> 34.1 | J23: =IFERROR(HYPERLINK(VLOOKUP($A23,Mythen!$A$3:$F$44,6,FALSE()),"Faktenkarte öffnen ↗"),"") -> Faktenkarte öffnen ↗
A24: =IFERROR(INDEX(Live!$A$2:$A$43,MATCH(11,Live!$P$2:$P$43,0)),"") -> 11 | B24: =IFERROR(INDEX(Live!$B$2:$B$43,MATCH(11,Live!$P$2:$P$43,0)),"") -> Cannabiskonsum bewirkt Übelkeit und Erbrechen. | C24: =IFERROR(INDEX(Live!$C$2:$C$43,MATCH(11,Live!$P$2:$P$43,0)),"") -> Risiken für den Körper und die Entwicklung | D24: =IFERROR(INDEX(Live!$D$2:$D$43,MATCH(11,Live!$P$2:$P$43,0)),"") -> Richtig | E24: =IFERROR(INDEX(Live!$E$2:$E$43,MATCH(11,Live!$P$2:$P$43,0)),"") -> 17.95 | F24: =IFERROR(INDEX(Live!$F$2:$F$43,MATCH(11,Live!$P$2:$P$43,0)),"") -> 60.15 | G24: =IFERROR(INDEX(Live!$G$2:$G$43,MATCH(11,Live!$P$2:$P$43,0)),"") -> 71.89 | H24: =IFERROR(INDEX(Live!$H$2:$H$43,MATCH(11,Live!$P$2:$P$43,0)),"") -> 25.78 | I24: =IFERROR(INDEX(Live!$I$2:$I$43,MATCH(11,Live!$P$2:$P$43,0)),"") -> 5.5 | J24: =IFERROR(HYPERLINK(VLOOKUP($A24,Mythen!$A$3:$F$44,6,FALSE()),"Faktenkarte öffnen ↗"),"") -> Faktenkarte öffnen ↗
A25: =IFERROR(INDEX(Live!$A$2:$A$43,MATCH(12,Live!$P$2:$P$43,0)),"") -> 12 | B25: =IFERROR(INDEX(Live!$B$2:$B$43,MATCH(12,Live!$P$2:$P$43,0)),"") -> Cannabis hemmt Entzündungen. | C25: =IFERROR(INDEX(Live!$C$2:$C$43,MATCH(12,Live!$P$2:$P$43,0)),"") -> Medizinischer und therapeutischer Nutzen | D25: =IFERROR(INDEX(Live!$D$2:$D$43,MATCH(12,Live!$P$2:$P$43,0)),"") -> Keine Aussage möglich | E25: =IFERROR(INDEX(Live!$E$2:$E$43,MATCH(12,Live!$P$2:$P$43,0)),"") -> 23.28 | F25: =IFERROR(INDEX(Live!$F$2:$F$43,MATCH(12,Live!$P$2:$P$43,0)),"") -> 69.36 | G25: =IFERROR(INDEX(Live!$G$2:$G$43,MATCH(12,Live!$P$2:$P$43,0)),"") | H25: =IFERROR(INDEX(Live!$H$2:$H$43,MATCH(12,Live!$P$2:$P$43,0)),"") | I25: =IFERROR(INDEX(Live!$I$2:$I$43,MATCH(12,Live!$P$2:$P$43,0)),"") | J25: =IFERROR(HYPERLINK(VLOOKUP($A25,Mythen!$A$3:$F$44,6,FALSE()),"Faktenkarte öffnen ↗"),"") -> Faktenkarte öffnen ↗
A26: =IFERROR(INDEX(Live!$A$2:$A$43,MATCH(13,Live!$P$2:$P$43,0)),"") -> 13 | B26: =IFERROR(INDEX(Live!$B$2:$B$43,MATCH(13,Live!$P$2:$P$43,0)),"") -> Cannabiskonsum löst Spasmen. | C26: =IFERROR(INDEX(Live!$C$2:$C$43,MATCH(13,Live!$P$2:$P$43,0)),"") -> Medizinischer und therapeutischer Nutzen | D26: =IFERROR(INDEX(Live!$D$2:$D$43,MATCH(13,Live!$P$2:$P$43,0)),"") -> Richtig | E26: =IFERROR(INDEX(Live!$E$2:$E$43,MATCH(13,Live!$P$2:$P$43,0)),"") -> 28.64 | F26: =IFERROR(INDEX(Live!$F$2:$F$43,MATCH(13,Live!$P$2:$P$43,0)),"") -> 59.71 | G26: =IFERROR(INDEX(Live!$G$2:$G$43,MATCH(13,Live!$P$2:$P$43,0)),"") -> 78.32 | H26: =IFERROR(INDEX(Live!$H$2:$H$43,MATCH(13,Live!$P$2:$P$43,0)),"") -> 22.81 | I26: =IFERROR(INDEX(Live!$I$2:$I$43,MATCH(13,Live!$P$2:$P$43,0)),"") -> 7.9 | J26: =IFERROR(HYPERLINK(VLOOKUP($A26,Mythen!$A$3:$F$44,6,FALSE()),"Faktenkarte öffnen ↗"),"") -> Faktenkarte öffnen ↗
A27: =IFERROR(INDEX(Live!$A$2:$A$43,MATCH(14,Live!$P$2:$P$43,0)),"") -> 14 | B27: =IFERROR(INDEX(Live!$B$2:$B$43,MATCH(14,Live!$P$2:$P$43,0)),"") -> Cannabiskonsum verursacht Herz-Kreislauferkrankungen. | C27: =IFERROR(INDEX(Live!$C$2:$C$43,MATCH(14,Live!$P$2:$P$43,0)),"") -> Risiken für den Körper und die Entwicklung | D27: =IFERROR(INDEX(Live!$D$2:$D$43,MATCH(14,Live!$P$2:$P$43,0)),"") -> Richtig | E27: =IFERROR(INDEX(Live!$E$2:$E$43,MATCH(14,Live!$P$2:$P$43,0)),"") -> 14.96 | F27: =IFERROR(INDEX(Live!$F$2:$F$43,MATCH(14,Live!$P$2:$P$43,0)),"") -> 75.94 | G27: =IFERROR(INDEX(Live!$G$2:$G$43,MATCH(14,Live!$P$2:$P$43,0)),"") -> 76.21 | H27: =IFERROR(INDEX(Live!$H$2:$H$43,MATCH(14,Live!$P$2:$P$43,0)),"") -> 29.92 | I27: =IFERROR(INDEX(Live!$I$2:$I$43,MATCH(14,Live!$P$2:$P$43,0)),"") -> 5.1 | J27: =IFERROR(HYPERLINK(VLOOKUP($A27,Mythen!$A$3:$F$44,6,FALSE()),"Faktenkarte öffnen ↗"),"") -> Faktenkarte öffnen ↗
A28: =IFERROR(INDEX(Live!$A$2:$A$43,MATCH(15,Live!$P$2:$P$43,0)),"") -> 15 | B28: =IFERROR(INDEX(Live!$B$2:$B$43,MATCH(15,Live!$P$2:$P$43,0)),"") -> Inhalativer Cannabiskonsum bewirkt Atemwegserkrankungen. | C28: =IFERROR(INDEX(Live!$C$2:$C$43,MATCH(15,Live!$P$2:$P$43,0)),"") -> Risiken für den Körper und die Entwicklung | D28: =IFERROR(INDEX(Live!$D$2:$D$43,MATCH(15,Live!$P$2:$P$43,0)),"") -> Richtig | E28: =IFERROR(INDEX(Live!$E$2:$E$43,MATCH(15,Live!$P$2:$P$43,0)),"") -> 16.03 | F28: =IFERROR(INDEX(Live!$F$2:$F$43,MATCH(15,Live!$P$2:$P$43,0)),"") -> 69.73 | G28: =IFERROR(INDEX(Live!$G$2:$G$43,MATCH(15,Live!$P$2:$P$43,0)),"") -> 78.8 | H28: =IFERROR(INDEX(Live!$H$2:$H$43,MATCH(15,Live!$P$2:$P$43,0)),"") -> 25.72 | I28: =IFERROR(INDEX(Live!$I$2:$I$43,MATCH(15,Live!$P$2:$P$43,0)),"") -> 4.9 | J28: =IFERROR(HYPERLINK(VLOOKUP($A28,Mythen!$A$3:$F$44,6,FALSE()),"Faktenkarte öffnen ↗"),"") -> Faktenkarte öffnen ↗
A29: =IFERROR(INDEX(Live!$A$2:$A$43,MATCH(16,Live!$P$2:$P$43,0)),"") -> 16 | B29: =IFERROR(INDEX(Live!$B$2:$B$43,MATCH(16,Live!$P$2:$P$43,0)),"") -> Cannabiskonsum verursacht Krebserkrankungen. | C29: =IFERROR(INDEX(Live!$C$2:$C$43,MATCH(16,Live!$P$2:$P$43,0)),"") -> Risiken für den Körper und die Entwicklung | D29: =IFERROR(INDEX(Live!$D$2:$D$43,MATCH(16,Live!$P$2:$P$43,0)),"") -> Richtig | E29: =IFERROR(INDEX(Live!$E$2:$E$43,MATCH(16,Live!$P$2:$P$43,0)),"") -> 10.12 | F29: =IFERROR(INDEX(Live!$F$2:$F$43,MATCH(16,Live!$P$2:$P$43,0)),"") -> 72.33 | G29: =IFERROR(INDEX(Live!$G$2:$G$43,MATCH(16,Live!$P$2:$P$43,0)),"") -> 73.59 | H29: =IFERROR(INDEX(Live!$H$2:$H$43,MATCH(16,Live!$P$2:$P$43,0)),"") -> 29.95 | I29: =IFERROR(INDEX(Live!$I$2:$I$43,MATCH(16,Live!$P$2:$P$43,0)),"") -> 3.5 | J29: =IFERROR(HYPERLINK(VLOOKUP($A29,Mythen!$A$3:$F$44,6,FALSE()),"Faktenkarte öffnen ↗"),"") -> Faktenkarte öffnen ↗
A30: =IFERROR(INDEX(Live!$A$2:$A$43,MATCH(17,Live!$P$2:$P$43,0)),"") -> 17 | B30: =IFERROR(INDEX(Live!$B$2:$B$43,MATCH(17,Live!$P$2:$P$43,0)),"") -> Cannabiskonsum hilft beim Abnehmen. | C30: =IFERROR(INDEX(Live!$C$2:$C$43,MATCH(17,Live!$P$2:$P$43,0)),"") -> Medizinischer und therapeutischer Nutzen | D30: =IFERROR(INDEX(Live!$D$2:$D$43,MATCH(17,Live!$P$2:$P$43,0)),"") -> Keine Aussage möglich | E30: =IFERROR(INDEX(Live!$E$2:$E$43,MATCH(17,Live!$P$2:$P$43,0)),"") -> 5.55 | F30: =IFERROR(INDEX(Live!$F$2:$F$43,MATCH(17,Live!$P$2:$P$43,0)),"") -> 48.94 | G30: =IFERROR(INDEX(Live!$G$2:$G$43,MATCH(17,Live!$P$2:$P$43,0)),"") | H30: =IFERROR(INDEX(Live!$H$2:$H$43,MATCH(17,Live!$P$2:$P$43,0)),"") | I30: =IFERROR(INDEX(Live!$I$2:$I$43,MATCH(17,Live!$P$2:$P$43,0)),"") | J30: =IFERROR(HYPERLINK(VLOOKUP($A30,Mythen!$A$3:$F$44,6,FALSE()),"Faktenkarte öffnen ↗"),"") -> Faktenkarte öffnen ↗
A31: =IFERROR(INDEX(Live!$A$2:$A$43,MATCH(18,Live!$P$2:$P$43,0)),"") -> 18 | B31: =IFERROR(INDEX(Live!$B$2:$B$43,MATCH(18,Live!$P$2:$P$43,0)),"") -> Cannabiskonsum hilft bei Schlafproblemen. | C31: =IFERROR(INDEX(Live!$C$2:$C$43,MATCH(18,Live!$P$2:$P$43,0)),"") -> Medizinischer und therapeutischer Nutzen | D31: =IFERROR(INDEX(Live!$D$2:$D$43,MATCH(18,Live!$P$2:$P$43,0)),"") -> Eher falsch | E31: =IFERROR(INDEX(Live!$E$2:$E$43,MATCH(18,Live!$P$2:$P$43,0)),"") -> 38.63 | F31: =IFERROR(INDEX(Live!$F$2:$F$43,MATCH(18,Live!$P$2:$P$43,0)),"") -> 61.87 | G31: =IFERROR(INDEX(Live!$G$2:$G$43,MATCH(18,Live!$P$2:$P$43,0)),"") -> 56.37 | H31: =IFERROR(INDEX(Live!$H$2:$H$43,MATCH(18,Live!$P$2:$P$43,0)),"") -> 39.33 | I31: =IFERROR(INDEX(Live!$I$2:$I$43,MATCH(18,Live!$P$2:$P$43,0)),"") -> 16.7 | J31: =IFERROR(HYPERLINK(VLOOKUP($A31,Mythen!$A$3:$F$44,6,FALSE()),"Faktenkarte öffnen ↗"),"") -> Faktenkarte öffnen ↗
A32: =IFERROR(INDEX(Live!$A$2:$A$43,MATCH(19,Live!$P$2:$P$43,0)),"") -> 19 | B32: =IFERROR(INDEX(Live!$B$2:$B$43,MATCH(19,Live!$P$2:$P$43,0)),"") -> Cannabiskonsum verändert die Wahrnehmungen. | C32: =IFERROR(INDEX(Live!$C$2:$C$43,MATCH(19,Live!$P$2:$P$43,0)),"") -> Einfluss auf Stimmung und Wahrnehmung | D32: =IFERROR(INDEX(Live!$D$2:$D$43,MATCH(19,Live!$P$2:$P$43,0)),"") -> Richtig | E32: =IFERROR(INDEX(Live!$E$2:$E$43,MATCH(19,Live!$P$2:$P$43,0)),"") -> 60.56 | F32: =IFERROR(INDEX(Live!$F$2:$F$43,MATCH(19,Live!$P$2:$P$43,0)),"") -> 71.83 | G32: =IFERROR(INDEX(Live!$G$2:$G$43,MATCH(19,Live!$P$2:$P$43,0)),"") -> 87.56 | H32: =IFERROR(INDEX(Live!$H$2:$H$43,MATCH(19,Live!$P$2:$P$43,0)),"") -> 21.45 | I32: =IFERROR(INDEX(Live!$I$2:$I$43,MATCH(19,Live!$P$2:$P$43,0)),"") -> 16 | J32: =IFERROR(HYPERLINK(VLOOKUP($A32,Mythen!$A$3:$F$44,6,FALSE()),"Faktenkarte öffnen ↗"),"") -> Faktenkarte öffnen ↗
A33: =IFERROR(INDEX(Live!$A$2:$A$43,MATCH(20,Live!$P$2:$P$43,0)),"") -> 20 | B33: =IFERROR(INDEX(Live!$B$2:$B$43,MATCH(20,Live!$P$2:$P$43,0)),"") -> Cannabiskonsum beeinträchtigt kognitive Fähigkeiten. | C33: =IFERROR(INDEX(Live!$C$2:$C$43,MATCH(20,Live!$P$2:$P$43,0)),"") -> Risiken für die psychische Gesundheit | D33: =IFERROR(INDEX(Live!$D$2:$D$43,MATCH(20,Live!$P$2:$P$43,0)),"") -> Richtig | E33: =IFERROR(INDEX(Live!$E$2:$E$43,MATCH(20,Live!$P$2:$P$43,0)),"") -> 44.28 | F33: =IFERROR(INDEX(Live!$F$2:$F$43,MATCH(20,Live!$P$2:$P$43,0)),"") -> 71.41 | G33: =IFERROR(INDEX(Live!$G$2:$G$43,MATCH(20,Live!$P$2:$P$43,0)),"") -> 83.34 | H33: =IFERROR(INDEX(Live!$H$2:$H$43,MATCH(20,Live!$P$2:$P$43,0)),"") -> 23.88 | I33: =IFERROR(INDEX(Live!$I$2:$I$43,MATCH(20,Live!$P$2:$P$43,0)),"") -> 12.7 | J33: =IFERROR(HYPERLINK(VLOOKUP($A33,Mythen!$A$3:$F$44,6,FALSE()),"Faktenkarte öffnen ↗"),"") -> Faktenkarte öffnen ↗
A34: =IFERROR(INDEX(Live!$A$2:$A$43,MATCH(21,Live!$P$2:$P$43,0)),"") -> 21 | B34: =IFERROR(INDEX(Live!$B$2:$B$43,MATCH(21,Live!$P$2:$P$43,0)),"") -> Cannabiskonsum gefährdet die Verkehrssicherheit. | C34: =IFERROR(INDEX(Live!$C$2:$C$43,MATCH(21,Live!$P$2:$P$43,0)),"") -> Soziale Auswirkungen und Leistungsfähigkeit | D34: =IFERROR(INDEX(Live!$D$2:$D$43,MATCH(21,Live!$P$2:$P$43,0)),"") -> Richtig | E34: =IFERROR(INDEX(Live!$E$2:$E$43,MATCH(21,Live!$P$2:$P$43,0)),"") -> 64.45 | F34: =IFERROR(INDEX(Live!$F$2:$F$43,MATCH(21,Live!$P$2:$P$43,0)),"") -> 82.84 | G34: =IFERROR(INDEX(Live!$G$2:$G$43,MATCH(21,Live!$P$2:$P$43,0)),"") -> 91.71 | H34: =IFERROR(INDEX(Live!$H$2:$H$43,MATCH(21,Live!$P$2:$P$43,0)),"") -> 21.4 | I34: =IFERROR(INDEX(Live!$I$2:$I$43,MATCH(21,Live!$P$2:$P$43,0)),"") -> 17 | J34: =IFERROR(HYPERLINK(VLOOKUP($A34,Mythen!$A$3:$F$44,6,FALSE()),"Faktenkarte öffnen ↗"),"") -> Faktenkarte öffnen ↗
A35: =IFERROR(INDEX(Live!$A$2:$A$43,MATCH(22,Live!$P$2:$P$43,0)),"") -> 22 | B35: =IFERROR(INDEX(Live!$B$2:$B$43,MATCH(22,Live!$P$2:$P$43,0)),"") -> Cannabis ist eine Einstiegsdroge. | C35: =IFERROR(INDEX(Live!$C$2:$C$43,MATCH(22,Live!$P$2:$P$43,0)),"") -> Risiken für die psychische Gesundheit | D35: =IFERROR(INDEX(Live!$D$2:$D$43,MATCH(22,Live!$P$2:$P$43,0)),"") -> Eher falsch | E35: =IFERROR(INDEX(Live!$E$2:$E$43,MATCH(22,Live!$P$2:$P$43,0)),"") -> 58.07 | F35: =IFERROR(INDEX(Live!$F$2:$F$43,MATCH(22,Live!$P$2:$P$43,0)),"") -> 66.83 | G35: =IFERROR(INDEX(Live!$G$2:$G$43,MATCH(22,Live!$P$2:$P$43,0)),"") -> 51.65 | H35: =IFERROR(INDEX(Live!$H$2:$H$43,MATCH(22,Live!$P$2:$P$43,0)),"") -> 44.41 | I35: =IFERROR(INDEX(Live!$I$2:$I$43,MATCH(22,Live!$P$2:$P$43,0)),"") -> 27.8 | J35: =IFERROR(HYPERLINK(VLOOKUP($A35,Mythen!$A$3:$F$44,6,FALSE()),"Faktenkarte öffnen ↗"),"") -> Faktenkarte öffnen ↗
A36: =IFERROR(INDEX(Live!$A$2:$A$43,MATCH(23,Live!$P$2:$P$43,0)),"") -> 23 | B36: =IFERROR(INDEX(Live!$B$2:$B$43,MATCH(23,Live!$P$2:$P$43,0)),"") -> Cannabis verursacht keine Abhängigkeit. | C36: =IFERROR(INDEX(Live!$C$2:$C$43,MATCH(23,Live!$P$2:$P$43,0)),"") -> Risiken für die psychische Gesundheit | D36: =IFERROR(INDEX(Live!$D$2:$D$43,MATCH(23,Live!$P$2:$P$43,0)),"") -> Falsch | E36: =IFERROR(INDEX(Live!$E$2:$E$43,MATCH(23,Live!$P$2:$P$43,0)),"") -> 16.43 | F36: =IFERROR(INDEX(Live!$F$2:$F$43,MATCH(23,Live!$P$2:$P$43,0)),"") -> 58.35 | G36: =IFERROR(INDEX(Live!$G$2:$G$43,MATCH(23,Live!$P$2:$P$43,0)),"") -> 63.75 | H36: =IFERROR(INDEX(Live!$H$2:$H$43,MATCH(23,Live!$P$2:$P$43,0)),"") -> 33.68 | I36: =IFERROR(INDEX(Live!$I$2:$I$43,MATCH(23,Live!$P$2:$P$43,0)),"") -> 6.2 | J36: =IFERROR(HYPERLINK(VLOOKUP($A36,Mythen!$A$3:$F$44,6,FALSE()),"Faktenkarte öffnen ↗"),"") -> Faktenkarte öffnen ↗
A37: =IFERROR(INDEX(Live!$A$2:$A$43,MATCH(24,Live!$P$2:$P$43,0)),"") -> 24 | B37: =IFERROR(INDEX(Live!$B$2:$B$43,MATCH(24,Live!$P$2:$P$43,0)),"") -> Cannabiskonsum verursacht Psychosen. | C37: =IFERROR(INDEX(Live!$C$2:$C$43,MATCH(24,Live!$P$2:$P$43,0)),"") -> Risiken für die psychische Gesundheit | D37: =IFERROR(INDEX(Live!$D$2:$D$43,MATCH(24,Live!$P$2:$P$43,0)),"") -> Richtig | E37: =IFERROR(INDEX(Live!$E$2:$E$43,MATCH(24,Live!$P$2:$P$43,0)),"") -> 39.06 | F37: =IFERROR(INDEX(Live!$F$2:$F$43,MATCH(24,Live!$P$2:$P$43,0)),"") -> 69.6 | G37: =IFERROR(INDEX(Live!$G$2:$G$43,MATCH(24,Live!$P$2:$P$43,0)),"") -> 74.25 | H37: =IFERROR(INDEX(Live!$H$2:$H$43,MATCH(24,Live!$P$2:$P$43,0)),"") -> 28.48 | I37: =IFERROR(INDEX(Live!$I$2:$I$43,MATCH(24,Live!$P$2:$P$43,0)),"") -> 12.9 | J37: =IFERROR(HYPERLINK(VLOOKUP($A37,Mythen!$A$3:$F$44,6,FALSE()),"Faktenkarte öffnen ↗"),"") -> Faktenkarte öffnen ↗
A38: =IFERROR(INDEX(Live!$A$2:$A$43,MATCH(25,Live!$P$2:$P$43,0)),"") -> 25 | B38: =IFERROR(INDEX(Live!$B$2:$B$43,MATCH(25,Live!$P$2:$P$43,0)),"") -> Cannabiskonsum wirkt gegen Angst. | C38: =IFERROR(INDEX(Live!$C$2:$C$43,MATCH(25,Live!$P$2:$P$43,0)),"") -> Medizinischer und therapeutischer Nutzen | D38: =IFERROR(INDEX(Live!$D$2:$D$43,MATCH(25,Live!$P$2:$P$43,0)),"") -> Eher falsch | E38: =IFERROR(INDEX(Live!$E$2:$E$43,MATCH(25,Live!$P$2:$P$43,0)),"") -> 32.18 | F38: =IFERROR(INDEX(Live!$F$2:$F$43,MATCH(25,Live!$P$2:$P$43,0)),"") -> 60.49 | G38: =IFERROR(INDEX(Live!$G$2:$G$43,MATCH(25,Live!$P$2:$P$43,0)),"") -> 60.6 | H38: =IFERROR(INDEX(Live!$H$2:$H$43,MATCH(25,Live!$P$2:$P$43,0)),"") -> 35.85 | I38: =IFERROR(INDEX(Live!$I$2:$I$43,MATCH(25,Live!$P$2:$P$43,0)),"") -> 12.8 | J38: =IFERROR(HYPERLINK(VLOOKUP($A38,Mythen!$A$3:$F$44,6,FALSE()),"Faktenkarte öffnen ↗"),"") -> Faktenkarte öffnen ↗
A39: =IFERROR(INDEX(Live!$A$2:$A$43,MATCH(26,Live!$P$2:$P$43,0)),"") -> 26 | B39: =IFERROR(INDEX(Live!$B$2:$B$43,MATCH(26,Live!$P$2:$P$43,0)),"") -> Cannabiskonsum wirkt gegen Depressionen. | C39: =IFERROR(INDEX(Live!$C$2:$C$43,MATCH(26,Live!$P$2:$P$43,0)),"") -> Medizinischer und therapeutischer Nutzen | D39: =IFERROR(INDEX(Live!$D$2:$D$43,MATCH(26,Live!$P$2:$P$43,0)),"") -> Falsch | E39: =IFERROR(INDEX(Live!$E$2:$E$43,MATCH(26,Live!$P$2:$P$43,0)),"") -> 31.26 | F39: =IFERROR(INDEX(Live!$F$2:$F$43,MATCH(26,Live!$P$2:$P$43,0)),"") -> 62.58 | G39: =IFERROR(INDEX(Live!$G$2:$G$43,MATCH(26,Live!$P$2:$P$43,0)),"") -> 30.18 | H39: =IFERROR(INDEX(Live!$H$2:$H$43,MATCH(26,Live!$P$2:$P$43,0)),"") -> 54.67 | I39: =IFERROR(INDEX(Live!$I$2:$I$43,MATCH(26,Live!$P$2:$P$43,0)),"") -> 18 | J39: =IFERROR(HYPERLINK(VLOOKUP($A39,Mythen!$A$3:$F$44,6,FALSE()),"Faktenkarte öffnen ↗"),"") -> Faktenkarte öffnen ↗
A40: =IFERROR(INDEX(Live!$A$2:$A$43,MATCH(27,Live!$P$2:$P$43,0)),"") -> 27 | B40: =IFERROR(INDEX(Live!$B$2:$B$43,MATCH(27,Live!$P$2:$P$43,0)),"") -> Cannabiskonsum wirkt gegen ADHS. | C40: =IFERROR(INDEX(Live!$C$2:$C$43,MATCH(27,Live!$P$2:$P$43,0)),"") -> Medizinischer und therapeutischer Nutzen | D40: =IFERROR(INDEX(Live!$D$2:$D$43,MATCH(27,Live!$P$2:$P$43,0)),"") -> Eher falsch | E40: =IFERROR(INDEX(Live!$E$2:$E$43,MATCH(27,Live!$P$2:$P$43,0)),"") -> 30.37 | F40: =IFERROR(INDEX(Live!$F$2:$F$43,MATCH(27,Live!$P$2:$P$43,0)),"") -> 60.45 | G40: =IFERROR(INDEX(Live!$G$2:$G$43,MATCH(27,Live!$P$2:$P$43,0)),"") -> 55.93 | H40: =IFERROR(INDEX(Live!$H$2:$H$43,MATCH(27,Live!$P$2:$P$43,0)),"") -> 38.24 | I40: =IFERROR(INDEX(Live!$I$2:$I$43,MATCH(27,Live!$P$2:$P$43,0)),"") -> 12.8 | J40: =IFERROR(HYPERLINK(VLOOKUP($A40,Mythen!$A$3:$F$44,6,FALSE()),"Faktenkarte öffnen ↗"),"") -> Faktenkarte öffnen ↗
A41: =IFERROR(INDEX(Live!$A$2:$A$43,MATCH(28,Live!$P$2:$P$43,0)),"") -> 28 | B41: =IFERROR(INDEX(Live!$B$2:$B$43,MATCH(28,Live!$P$2:$P$43,0)),"") -> Cannabiskonsum verursacht einen generellen Motivationsverlust. | C41: =IFERROR(INDEX(Live!$C$2:$C$43,MATCH(28,Live!$P$2:$P$43,0)),"") -> Risiken für die psychische Gesundheit | D41: =IFERROR(INDEX(Live!$D$2:$D$43,MATCH(28,Live!$P$2:$P$43,0)),"") -> Falsch | E41: =IFERROR(INDEX(Live!$E$2:$E$43,MATCH(28,Live!$P$2:$P$43,0)),"") -> 26.29 | F41: =IFERROR(INDEX(Live!$F$2:$F$43,MATCH(28,Live!$P$2:$P$43,0)),"") -> 66.83 | G41: =IFERROR(INDEX(Live!$G$2:$G$43,MATCH(28,Live!$P$2:$P$43,0)),"") -> 25.05 | H41: =IFERROR(INDEX(Live!$H$2:$H$43,MATCH(28,Live!$P$2:$P$43,0)),"") -> 60.32 | I41: =IFERROR(INDEX(Live!$I$2:$I$43,MATCH(28,Live!$P$2:$P$43,0)),"") -> 16.5 | J41: =IFERROR(HYPERLINK(VLOOKUP($A41,Mythen!$A$3:$F$44,6,FALSE()),"Faktenkarte öffnen ↗"),"") -> Faktenkarte öffnen ↗
A42: =IFERROR(INDEX(Live!$A$2:$A$43,MATCH(29,Live!$P$2:$P$43,0)),"") -> 29 | B42: =IFERROR(INDEX(Live!$B$2:$B$43,MATCH(29,Live!$P$2:$P$43,0)),"") -> Cannabiskonsum verbessert die Gemütslage. | C42: =IFERROR(INDEX(Live!$C$2:$C$43,MATCH(29,Live!$P$2:$P$43,0)),"") -> Einfluss auf Stimmung und Wahrnehmung | D42: =IFERROR(INDEX(Live!$D$2:$D$43,MATCH(29,Live!$P$2:$P$43,0)),"") -> Eher richtig | E42: =IFERROR(INDEX(Live!$E$2:$E$43,MATCH(29,Live!$P$2:$P$43,0)),"") -> 32.89 | F42: =IFERROR(INDEX(Live!$F$2:$F$43,MATCH(29,Live!$P$2:$P$43,0)),"") -> 59.2 | G42: =IFERROR(INDEX(Live!$G$2:$G$43,MATCH(29,Live!$P$2:$P$43,0)),"") -> 84.4 | H42: =IFERROR(INDEX(Live!$H$2:$H$43,MATCH(29,Live!$P$2:$P$43,0)),"") -> 21.23 | I42: =IFERROR(INDEX(Live!$I$2:$I$43,MATCH(29,Live!$P$2:$P$43,0)),"") -> 8.6 | J42: =IFERROR(HYPERLINK(VLOOKUP($A42,Mythen!$A$3:$F$44,6,FALSE()),"Faktenkarte öffnen ↗"),"") -> Faktenkarte öffnen ↗
A43: =IFERROR(INDEX(Live!$A$2:$A$43,MATCH(30,Live!$P$2:$P$43,0)),"") -> 30 | B43: =IFERROR(INDEX(Live!$B$2:$B$43,MATCH(30,Live!$P$2:$P$43,0)),"") -> Cannabiskonsum führt zu Suizidgedanken. | C43: =IFERROR(INDEX(Live!$C$2:$C$43,MATCH(30,Live!$P$2:$P$43,0)),"") -> Risiken für die psychische Gesundheit | D43: =IFERROR(INDEX(Live!$D$2:$D$43,MATCH(30,Live!$P$2:$P$43,0)),"") -> Eher richtig | E43: =IFERROR(INDEX(Live!$E$2:$E$43,MATCH(30,Live!$P$2:$P$43,0)),"") -> 14.09 | F43: =IFERROR(INDEX(Live!$F$2:$F$43,MATCH(30,Live!$P$2:$P$43,0)),"") -> 73.29 | G43: =IFERROR(INDEX(Live!$G$2:$G$43,MATCH(30,Live!$P$2:$P$43,0)),"") -> 83.02 | H43: =IFERROR(INDEX(Live!$H$2:$H$43,MATCH(30,Live!$P$2:$P$43,0)),"") -> 25.83 | I43: =IFERROR(INDEX(Live!$I$2:$I$43,MATCH(30,Live!$P$2:$P$43,0)),"") -> 4.3 | J43: =IFERROR(HYPERLINK(VLOOKUP($A43,Mythen!$A$3:$F$44,6,FALSE()),"Faktenkarte öffnen ↗"),"") -> Faktenkarte öffnen ↗
...

Sheet Erläuterungen
A1: Erläuterungen — Begriffe und Lesehinweise zum Daten-Explorer
A3: Worum geht es? | B3: Diese Datei zeigt die Ergebnisse des Forschungsprojekts CaRM (Cannabis – Risiken und Mythen, ISD Hamburg) zu 42 Mythen rund um Cannabis. Sie ist als Arbeitshilfe für Präventionsfachkräfte, Lehrkräfte und andere Multiplikator:innen gedacht. Über die Filter und die Sortierung lassen sich die Mythen schnell nach Themen, Klassifikation, Zielgruppe oder Indikatoren erschließen.
A4: Wichtig — keine Nachrechnung | B4: Die ausgewiesenen Werte sind das Ergebnis umfangreicher methodischer Transformationen: Standardisierung in den Wertebereich 0–100 (Punkte), Gewichtung für die Bevölkerungsgruppen Volljährige und Minderjährige. Eine eigenständige Nachrechnung anhand der hier gezeigten Zahlen ist nicht möglich, weil zu viele Zwischenschritte fehlen.
A5: Wissenschaftliche Klassifikation | B5: Vier Stufen plus 'Keine Aussage möglich': Richtig · Eher richtig · Eher falsch · Falsch. Basis: internationale Literatur bis September 2025. Für zwei Mythen (m12 Entzündungen, m17 Abnehmen) reicht die Evidenz für eine Einordnung nicht aus — sie tragen den Wert 'Keine Aussage möglich'.
A6: Datengrundlage | B6: Drei Erhebungspanels, Sommer 2025: 2.079 Volljährige (18–70, gewichtet), 555 Minderjährige (16–17, gewichtet), 143 aktuell Konsumierende über Anbauvereinigungen (ungewichtet). Quelle: ISD Hamburg, Forschungsprojekt CaRM.
A7: Zielgruppe | B7: Mit dem Dropdown 'Zielgruppe' wechseln alle Indikator-Spalten zwischen den fünf Befragungsgruppen: Volljährige, Minderjährige, aktuell Konsumierende, Junge Erwachsene (18–26) und Eltern minderjähriger Kinder.
A8: Kenntnis Mythos (in %) | B8: Anteil der Befragten in der gewählten Zielgruppe, der den Mythos kennt. Den Befragten wurden die 42 Mythen vorgelegt; sie haben die ausgewählt, die sie schon einmal gehört oder gelesen haben.
A9: Individuelle Bedeutung (Punkte 0–100) | B9: Wie wichtig ist der Mythos den Befragten für ihren eigenen Umgang mit Cannabis? Beurteilung auf einer vierstufigen Skala 'sehr wichtig' bis 'unwichtig', transformiert auf 0–100 Punkte (höher = bedeutsamer). Werte gelten jeweils nur für die Befragten, die den Mythos kennen.
A10: Richtigkeit der Beurteilung (Punkte 0–100) | B10: Wie nah liegt das Urteil der Befragten an der wissenschaftlichen Klassifikation? Beurteilung des Mythos vierstufig erhoben, dann mit der Einordnung der Wissenschaft abgeglichen und auf 0–100 transformiert. 0 = durchgehend konträr zur Wissenschaft · 100 = durchgehend übereinstimmend.
A11: Präventionsbedeutung (Punkte 0–100) | B11: Setzung des Projektteams: Bedeutsamkeit × invers(Richtigkeit). Ein hoher Wert bedeutet, der Mythos ist den Befragten wichtig UND wird falsch beurteilt — also präventionsrelevant. Zwei Faktoren multipliziert, anschließend auf 0–100 transformiert.
A12: Bevölkerungsrelevanz (Punkte 0–100) | B12: Nur für die Bevölkerungsgruppen Volljährige und Minderjährige ausgewiesen. Präventionsbedeutung × Kenntnisanteil — also: hoher Wert = bei vielen Menschen präventionsrelevant. Bei den Subzielgruppen (Konsumierende, Junge Erwachsene, Eltern) bleibt die Spalte leer; das entspricht der Auswertungslogik im CaRM-Projekt.
A13: Filter und Sortierung | B13: Filter (Zielgruppe, Klassifikation, Kategorie, Suche im Mythos-Text) und die beiden Sortierregler oben kombinieren sich. Das Feld 'Treffer' zeigt, wie viele der 42 Mythen aktuell sichtbar sind. 'Suche' ist eine Teilwort-Suche, Groß- und Kleinschreibung werden ignoriert.
A14: Faktenkarten (Hyperlinks) | B14: Jede Zeile endet mit einem Link 'Faktenkarte öffnen ↗' zur ausführlichen Faktenkarte des Mythos auf der CaRM-Website (cannabismythen.netlify.app/daten-explorer/...). Dort finden sich die ausführliche Begründung der Klassifikation und Quellen.
A15: Keine Repräsentativität | B15: Die Stichproben beziehen sich auf Erwachsene 18–70 und Minderjährige 16–17 in einer Bevölkerungsbefragung in Deutschland — nicht auf 'die Bevölkerung' im Sinne der gesamten 80 Mio. Menschen. Bitte diese Lesart bei der Weiterverwendung beibehalten.

Sheet Listen
A1: Zielgruppen | B1: Klassifikationen | C1: Kategorien | D1: Sortierfeld | E1: SpaltenIndex | F1: Reihenfolge | G1: Berechnet | H1: Klassifikation | I1: Reihenfolge
A2: Erwachsene (18–70) | B2: Alle | C2: Alle | D2: Mythos-Nr. | E2: 1 | F2: Aufsteigend | G2: =IFERROR(VLOOKUP(sortFeld,$D$2:$E$10,2,FALSE()),1) -> 1 | H2: Richtig | I2: 1
A3: Minderjährige (16–17) | B3: Richtig | C3: Medizinischer und therapeutischer Nutzen | D3: Mythos | E3: 2 | F3: Absteigend | G3: =IF(sortReihen="Absteigend",-1,1) -> 1 | H3: Eher richtig | I3: 2
A4: Konsumierende (letzte 30 Tage) | B4: Eher richtig | C4: Allgemeine Einschätzung der Gefährlichkeit | D4: Kategorie | E4: 3 | H4: Eher falsch | I4: 3
A5: Junge Erwachsene (18–26) | B5: Eher falsch | C5: Risiken durch Dosierung und Qualität | D5: Klassifikation | E5: 4 | H5: Falsch | I5: 4
A6: Eltern minderjähriger Kinder | B6: Falsch | C6: Risiken für den Körper und die Entwicklung | D6: Kenntnis % | E6: 5 | H6: Keine Aussage möglich | I6: 5
B7: Keine Aussage möglich | C7: Risiken für die psychische Gesundheit | D7: Bedeutung | E7: 6
C8: Einfluss auf Stimmung und Wahrnehmung | D8: Richtigkeit | E8: 7
C9: Soziale Auswirkungen und Leistungsfähigkeit | D9: Präv.-Bedeutung | E9: 8
C10: Verbreitung in der Bevölkerung und Gesetzgebung | D10: Bevölk.-Relevanz | E10: 9

Sheet Daten
A1: Daten-Lookup: Mythos × Zielgruppe × Indikatoren (Quelle: carm-data.json)
A2: myth_id | B2: group_id | C2: Zielgruppe | D2: Kenntnis % | E2: Bedeutung Pkt. | F2: Richtigkeit Pkt. | G2: Präventionsbedeutung Pkt. | H2: Bevölkerungsrelevanz Pkt.
A3: 1 | B3: adults | C3: Erwachsene (18–70) | D3: 12.32 | E3: 52.82 | F3: 49.1 | G3: 41.49 | H3: 5.6
A4: 1 | B4: minors | C4: Minderjährige (16–17) | D4: 20.29 | E4: 48.72 | F4: 47.29 | G4: 38.2 | H4: 8.5
A5: 1 | B5: consumers | C5: Konsumierende (letzte 30 Tage) | D5: 22.03 | E5: 54.17 | F5: 43.07 | G5: 46.36
A6: 1 | B6: young_adults | C6: Junge Erwachsene (18–26) | D6: 16.01 | E6: 53.47 | F6: 46.94 | G6: 43.19
A7: 1 | B7: parents | C7: Eltern minderjähriger Kinder | D7: 11.82 | E7: 52.46 | F7: 45.9 | G7: 42.62
A8: 2 | B8: adults | C8: Erwachsene (18–70) | D8: 18.02 | E8: 52.63 | F8: 63.77 | G8: 31.78 | H8: 6.5
A9: 2 | B9: minors | C9: Minderjährige (16–17) | D9: 21.26 | E9: 53.61 | F9: 66.76 | G9: 32.06 | H9: 7.7
A10: 2 | B10: consumers | C10: Konsumierende (letzte 30 Tage) | D10: 33.42 | E10: 61.15 | F10: 45.68 | G10: 45.96
A11: 2 | B11: young_adults | C11: Junge Erwachsene (18–26) | D11: 21.24 | E11: 60.94 | F11: 52.82 | G11: 41.04
A12: 2 | B12: parents | C12: Eltern minderjähriger Kinder | D12: 21.12 | E12: 49.24 | F12: 68.5 | G12: 27.83
A13: 3 | B13: adults | C13: Erwachsene (18–70) | D13: 48.64 | E13: 76.78 | F13: 77.93 | G13: 30.43 | H13: 16.9
A14: 3 | B14: minors | C14: Minderjährige (16–17) | D14: 46.36 | E14: 78.02 | F14: 74.75 | G14: 32.92 | H14: 17.2
A15: 3 | B15: consumers | C15: Konsumierende (letzte 30 Tage) | D15: 59.41 | E15: 69.58 | F15: 78.33 | G15: 27.67
A16: 3 | B16: young_adults | C16: Junge Erwachsene (18–26) | D16: 49.35 | E16: 69.76 | F16: 78.59 | G16: 27.59
A17: 3 | B17: parents | C17: Eltern minderjähriger Kinder | D17: 50.97 | E17: 80.41 | F17: 76.93 | G17: 32.19
A18: 4 | B18: adults | C18: Erwachsene (18–70) | D18: 35.16 | E18: 62.1 | F18: 69.66 | G18: 27.37 | H18: 11.2
A19: 4 | B19: minors | C19: Minderjährige (16–17) | D19: 34.58 | E19: 61.8 | F19: 61.47 | G19: 32.04 | H19: 12.5
A20: 4 | B20: consumers | C20: Konsumierende (letzte 30 Tage) | D20: 72.52 | E20: 75.09 | F20: 87.49 | G20: 21.98
A21: 4 | B21: young_adults | C21: Junge Erwachsene (18–26) | D21: 53.92 | E21: 67.07 | F21: 78.38 | G21: 24.48
A22: 4 | B22: parents | C22: Eltern minderjähriger Kinder | D22: 40.12 | E22: 65.06 | F22: 72.14 | G22: 27.18
A23: 5 | B23: adults | C23: Erwachsene (18–70) | D23: 16.33 | E23: 68.51 | F23: 76.43 | G23: 26.37 | H23: 5.1
A24: 5 | B24: minors | C24: Minderjährige (16–17) | D24: 27.68 | E24: 67.58 | F24: 67.47 | G24: 31.01 | H24: 9.8
A25: 5 | B25: consumers | C25: Konsumierende (letzte 30 Tage) | D25: 17.82 | E25: 54.17 | F25: 56.94 | G25: 30.83
A26: 5 | B26: young_adults | C26: Junge Erwachsene (18–26) | D26: 16.67 | E26: 67.32 | F26: 73.86 | G26: 28.1
A27: 5 | B27: parents | C27: Eltern minderjähriger Kinder | D27: 18.8 | E27: 64.26 | F27: 75.26 | G27: 25.36
A28: 6 | B28: adults | C28: Erwachsene (18–70) | D28: 43.75 | E28: 77.02 | F28: 88.97 | G28: 21.93 | H28: 11.7
A29: 6 | B29: minors | C29: Minderjährige (16–17) | D29: 48.83 | E29: 77.89 | F29: 88.2 | G29: 22.91 | H29: 13.5
A30: 6 | B30: consumers | C30: Konsumierende (letzte 30 Tage) | D30: 52.23 | E30: 67.61 | F30: 84.52 | G30: 21.17
A31: 6 | B31: young_adults | C31: Junge Erwachsene (18–26) | D31: 51.96 | E31: 75.26 | F31: 88.47 | G31: 21.3
A32: 6 | B32: parents | C32: Eltern minderjähriger Kinder | D32: 44.77 | E32: 76.19 | F32: 88.02 | G32: 22.08
A33: 7 | B33: adults | C33: Erwachsene (18–70) | D33: 35.06 | E33: 76.49 | F33: 85.7 | G33: 24.05 | H33: 10.1
A34: 7 | B34: minors | C34: Minderjährige (16–17) | D34: 42.85 | E34: 75.75 | F34: 81.81 | G34: 25.4 | H34: 12.9
A35: 7 | B35: consumers | C35: Konsumierende (letzte 30 Tage) | D35: 45.3 | E35: 77.66 | F35: 86.52 | G35: 23.66
A36: 7 | B36: young_adults | C36: Junge Erwachsene (18–26) | D36: 43.46 | E36: 76.01 | F36: 86.22 | G36: 23.28
A37: 7 | B37: parents | C37: Eltern minderjähriger Kinder | D37: 36.24 | E37: 80.75 | F37: 84.67 | G37: 26.13
A38: 8 | B38: adults | C38: Erwachsene (18–70) | D38: 42.35 | E38: 76.49 | F38: 89.87 | G38: 21.16 | H38: 11
A39: 8 | B39: minors | C39: Minderjährige (16–17) | D39: 41.83 | E39: 73.37 | F39: 85.42 | G39: 22.21 | H39: 11.3
A40: 8 | B40: consumers | C40: Konsumierende (letzte 30 Tage) | D40: 34.65 | E40: 68.81 | F40: 84.76 | G40: 21.95
...

Sheet Mythen
A1: Mythen-Stammdaten — 42 Einträge (final, Christian 2026-05) inkl. URL
A2: myth_id | B2: Mythos | C2: Klassifikation | D2: Kategorie | E2: Slug | F2: URL
A3: 1 | B3: Cannabis ist ein Allheilmittel. | C3: Falsch | D3: Medizinischer und therapeutischer Nutzen | E3: m01-allheilmittel | F3: https://cannabismythen.netlify.app/daten-explorer/m01-allheilmittel/
A4: 2 | B4: Cannabiskonsum ist harmlos. | C4: Falsch | D4: Allgemeine Einschätzung der Gefährlichkeit | E4: m02-harmlos | F4: https://cannabismythen.netlify.app/daten-explorer/m02-harmlos/
A5: 3 | B5: Cannabiskonsum durch Heranwachsende führt in stärkerem Maße als bei Erwachsenen zu gesundheitlichen Schäden. | C5: Eher richtig | D5: Allgemeine Einschätzung der Gefährlichkeit | E5: m03-heranwachsende | F5: https://cannabismythen.netlify.app/daten-explorer/m03-heranwachsende/
A6: 4 | B6: Cannabis ist weniger schädlich als Alkohol. | C6: Richtig | D6: Allgemeine Einschätzung der Gefährlichkeit | E6: m04-weniger-schaedlich-alkohol | F6: https://cannabismythen.netlify.app/daten-explorer/m04-weniger-schaedlich-alkohol/
A7: 5 | B7: Cannabis ist schwierig zu dosieren. | C7: Richtig | D7: Risiken durch Dosierung und Qualität | E7: m05-schwierig-dosieren | F7: https://cannabismythen.netlify.app/daten-explorer/m05-schwierig-dosieren/
A8: 6 | B8: Mischkonsum von Cannabis mit anderen Substanzen ist besonders risikoreich. | C8: Richtig | D8: Risiken durch Dosierung und Qualität | E8: m06-mischkonsum | F8: https://cannabismythen.netlify.app/daten-explorer/m06-mischkonsum/
A9: 7 | B9: Zusätze im Cannabis führen zu erhöhten Gesundheitsrisiken. | C9: Richtig | D9: Risiken durch Dosierung und Qualität | E9: m07-zusaetze | F9: https://cannabismythen.netlify.app/daten-explorer/m07-zusaetze/
A10: 8 | B10: Cannabiskonsum schädigt den Fötus. | C10: Richtig | D10: Risiken für den Körper und die Entwicklung | E10: m08-foetus | F10: https://cannabismythen.netlify.app/daten-explorer/m08-foetus/
A11: 9 | B11: Eine Überdosierung von Cannabis führt nicht zum Tod. | C11: Richtig | D11: Risiken durch Dosierung und Qualität | E11: m09-ueberdosierung | F11: https://cannabismythen.netlify.app/daten-explorer/m09-ueberdosierung/
A12: 10 | B12: Cannabis wirkt gegen Schmerzen. | C12: Eher falsch | D12: Medizinischer und therapeutischer Nutzen | E12: m10-schmerzen | F12: https://cannabismythen.netlify.app/daten-explorer/m10-schmerzen/
A13: 11 | B13: Cannabiskonsum bewirkt Übelkeit und Erbrechen. | C13: Richtig | D13: Risiken für den Körper und die Entwicklung | E13: m11-uebelkeit | F13: https://cannabismythen.netlify.app/daten-explorer/m11-uebelkeit/
A14: 12 | B14: Cannabis hemmt Entzündungen. | C14: Keine Aussage möglich | D14: Medizinischer und therapeutischer Nutzen | E14: m12-entzuendungen | F14: https://cannabismythen.netlify.app/daten-explorer/m12-entzuendungen/
... A44: 42 | B44: Die Teillegalisierung wird zu einem Anstieg des Cannabiskonsums unter Minderjährigen führen. | C44: Eher falsch | D44: Verbreitung in der Bevölkerung und Gesetzgebung | E44: m41-m42-anstieg-konsum | F44: https://cannabismythen.netlify.app/daten-explorer/m41-m42-anstieg-konsum/

Sheet Live
A1: myth_id | B1: Mythos | C1: Kategorie | D1: Klassifikation | E1: Kenntnis % | F1: Bedeutung | G1: Richtigkeit | H1: Präv.-Bedeutung | I1: Bevölk.-Relevanz | J1: _klassMatch | K1: _katMatch | L1: _sucheMatch | M1: _includeFlag | N1: _rawSort | O1: _sortKey | P1: _rank
A2: 1 | B2: Cannabis ist ein Allheilmittel. | C2: Medizinischer und therapeutischer Nutzen | D2: Falsch | E2: =IF(COUNTIFS(Daten[myth_id],1,Daten[Zielgruppe],selectedGroup,Daten[Kenntnis %],"<>")=0,"",SUMIFS(Daten[Kenntnis %],Daten[myth_id],1,Daten[Zielgruppe],selectedGroup)) -> 12.32 | F2: =IF(COUNTIFS(Daten[myth_id],1,Daten[Zielgruppe],selectedGroup,Daten[Bedeutung Pkt.],"<>")=0,"",SUMIFS(Daten[Bedeutung Pkt.],Daten[myth_id],1,Daten[Zielgruppe],selectedGroup)) -> 52.82 | G2: =IF(COUNTIFS(Daten[myth_id],1,Daten[Zielgruppe],selectedGroup,Daten[Richtigkeit Pkt.],"<>")=0,"",SUMIFS(Daten[Richtigkeit Pkt.],Daten[myth_id],1,Daten[Zielgruppe],selectedGroup)) -> 49.1 | H2: =IF(COUNTIFS(Daten[myth_id],1,Daten[Zielgruppe],selectedGroup,Daten[Präventionsbedeutung Pkt.],"<>")=0,"",SUMIFS(Daten[Präventionsbedeutung Pkt.],Daten[myth_id],1,Daten[Zielgruppe],selectedGroup)) -> 41.49 | I2: =IF(COUNTIFS(Daten[myth_id],1,Daten[Zielgruppe],selectedGroup,Daten[Bevölkerungsrelevanz Pkt.],"<>")=0,"",SUMIFS(Daten[Bevölkerungsrelevanz Pkt.],Daten[myth_id],1,Daten[Zielgruppe],selectedGroup)) -> 5.6 | J2: =IF(klassFilter="Alle",1,IF($D2=klassFilter,1,0)) -> 1 | K2: =IF(katFilter="Alle",1,IF($C2=katFilter,1,0)) -> 1 | L2: =IF(LEN(sucheText)=0,1,IFERROR(IF(ISNUMBER(SEARCH(sucheText,$B2)),1,0),0)) -> 1 | M2: =$J2*$K2*$L2 -> 1 | N2: =CHOOSE(sortIdx,$A2,COUNTIF(Live!$B$2:$B$43,"<"&$B2)+1,COUNTIF(Live!$C$2:$C$43,"<"&$C2)+1,IFERROR(VLOOKUP($D2,Listen!$H$2:$I$6,2,FALSE()),99),$E2,$F2,$G2,$H2,$I2) -> 1 | O2: =IF($N2="",100000,sortDir*$N2)+ROW()*0.0001 -> 1.0002 | P2: =IF($M2<>1,0,COUNTIFS(Live!$M$2:$M$43,1,Live!$O$2:$O$43,"<"&$O2)+1) -> 1
A3: 2 | B3: Cannabiskonsum ist harmlos. | C3: Allgemeine Einschätzung der Gefährlichkeit | D3: Falsch | E3: =IF(COUNTIFS(Daten[myth_id],2,Daten[Zielgruppe],selectedGroup,Daten[Kenntnis %],"<>")=0,"",SUMIFS(Daten[Kenntnis %],Daten[myth_id],2,Daten[Zielgruppe],selectedGroup)) -> 18.02 | F3: =IF(COUNTIFS(Daten[myth_id],2,Daten[Zielgruppe],selectedGroup,Daten[Bedeutung Pkt.],"<>")=0,"",SUMIFS(Daten[Bedeutung Pkt.],Daten[myth_id],2,Daten[Zielgruppe],selectedGroup)) -> 52.63 | G3: =IF(COUNTIFS(Daten[myth_id],2,Daten[Zielgruppe],selectedGroup,Daten[Richtigkeit Pkt.],"<>")=0,"",SUMIFS(Daten[Richtigkeit Pkt.],Daten[myth_id],2,Daten[Zielgruppe],selectedGroup)) -> 63.77 | H3: =IF(COUNTIFS(Daten[myth_id],2,Daten[Zielgruppe],selectedGroup,Daten[Präventionsbedeutung Pkt.],"<>")=0,"",SUMIFS(Daten[Präventionsbedeutung Pkt.],Daten[myth_id],2,Daten[Zielgruppe],selectedGroup)) -> 31.78 | I3: =IF(COUNTIFS(Daten[myth_id],2,Daten[Zielgruppe],selectedGroup,Daten[Bevölkerungsrelevanz Pkt.],"<>")=0,"",SUMIFS(Daten[Bevölkerungsrelevanz Pkt.],Daten[myth_id],2,Daten[Zielgruppe],selectedGroup)) -> 6.5 | J3: =IF(klassFilter="Alle",1,IF($D3=klassFilter,1,0)) -> 1 | K3: =IF(katFilter="Alle",1,IF($C3=katFilter,1,0)) -> 1 | L3: =IF(LEN(sucheText)=0,1,IFERROR(IF(ISNUMBER(SEARCH(sucheText,$B3)),1,0),0)) -> 1 | M3: =$J3*$K3*$L3 -> 1 | N3: =CHOOSE(sortIdx,$A3,COUNTIF(Live!$B$2:$B$43,"<"&$B3)+1,COUNTIF(Live!$C$2:$C$43,"<"&$C3)+1,IFERROR(VLOOKUP($D3,Listen!$H$2:$I$6,2,FALSE()),99),$E3,$F3,$G3,$H3,$I3) -> 2 | O3: =IF($N3="",100000,sortDir*$N3)+ROW()*0.0001 -> 2.0003 | P3: =IF($M3<>1,0,COUNTIFS(Live!$M$2:$M$43,1,Live!$O$2:$O$43,"<"&$O3)+1) -> 2
A4: 3 | B4: Cannabiskonsum durch Heranwachsende führt in stärkerem Maße als bei Erwachsenen zu gesundheitlichen Schäden. | C4: Allgemeine Einschätzung der Gefährlichkeit | D4: Eher richtig | E4: =IF(COUNTIFS(Daten[myth_id],3,Daten[Zielgruppe],selectedGroup,Daten[Kenntnis %],"<>")=0,"",SUMIFS(Daten[Kenntnis %],Daten[myth_id],3,Daten[Zielgruppe],selectedGroup)) -> 48.64 | F4: =IF(COUNTIFS(Daten[myth_id],3,Daten[Zielgruppe],selectedGroup,Daten[Bedeutung Pkt.],"<>")=0,"",SUMIFS(Daten[Bedeutung Pkt.],Daten[myth_id],3,Daten[Zielgruppe],selectedGroup)) -> 76.78 | G4: =IF(COUNTIFS(Daten[myth_id],3,Daten[Zielgruppe],selectedGroup,Daten[Richtigkeit Pkt.],"<>")=0,"",SUMIFS(Daten[Richtigkeit Pkt.],Daten[myth_id],3,Daten[Zielgruppe],selectedGroup)) -> 77.93 | H4: =IF(COUNTIFS(Daten[myth_id],3,Daten[Zielgruppe],selectedGroup,Daten[Präventionsbedeutung Pkt.],"<>")=0,"",SUMIFS(Daten[Präventionsbedeutung Pkt.],Daten[myth_id],3,Daten[Zielgruppe],selectedGroup)) -> 30.43 | I4: =IF(COUNTIFS(Daten[myth_id],3,Daten[Zielgruppe],selectedGroup,Daten[Bevölkerungsrelevanz Pkt.],"<>")=0,"",SUMIFS(Daten[Bevölkerungsrelevanz Pkt.],Daten[myth_id],3,Daten[Zielgruppe],selectedGroup)) -> 16.9 | J4: =IF(klassFilter="Alle",1,IF($D4=klassFilter,1,0)) -> 1 | K4: =IF(katFilter="Alle",1,IF($C4=katFilter,1,0)) -> 1 | L4: =IF(LEN(sucheText)=0,1,IFERROR(IF(ISNUMBER(SEARCH(sucheText,$B4)),1,0),0)) -> 1 | M4: =$J4*$K4*$L4 -> 1 | N4: =CHOOSE(sortIdx,$A4,COUNTIF(Live!$B$2:$B$43,"<"&$B4)+1,COUNTIF(Live!$C$2:$C$43,"<"&$C4)+1,IFERROR(VLOOKUP($D4,Listen!$H$2:$I$6,2,FALSE()),99),$E4,$F4,$G4,$H4,$I4) -> 3 | O4: =IF($N4="",100000,sortDir*$N4)+ROW()*0.0001 -> 3.0004 | P4: =IF($M4<>1,0,COUNTIFS(Live!$M$2:$M$43,1,Live!$O$2:$O$43,"<"&$O4)+1) -> 3
A5: 4 | B5: Cannabis ist weniger schädlich als Alkohol. | C5: Allgemeine Einschätzung der Gefährlichkeit | D5: Richtig | E5: =IF(COUNTIFS(Daten[myth_id],4,Daten[Zielgruppe],selectedGroup,Daten[Kenntnis %],"<>")=0,"",SUMIFS(Daten[Kenntnis %],Daten[myth_id],4,Daten[Zielgruppe],selectedGroup)) -> 35.16 | F5: =IF(COUNTIFS(Daten[myth_id],4,Daten[Zielgruppe],selectedGroup,Daten[Bedeutung Pkt.],"<>")=0,"",SUMIFS(Daten[Bedeutung Pkt.],Daten[myth_id],4,Daten[Zielgruppe],selectedGroup)) -> 62.1 | G5: =IF(COUNTIFS(Daten[myth_id],4,Daten[Zielgruppe],selectedGroup,Daten[Richtigkeit Pkt.],"<>")=0,"",SUMIFS(Daten[Richtigkeit Pkt.],Daten[myth_id],4,Daten[Zielgruppe],selectedGroup)) -> 69.66 | H5: =IF(COUNTIFS(Daten[myth_id],4,Daten[Zielgruppe],selectedGroup,Daten[Präventionsbedeutung Pkt.],"<>")=0,"",SUMIFS(Daten[Präventionsbedeutung Pkt.],Daten[myth_id],4,Daten[Zielgruppe],selectedGroup)) -> 27.37 | I5: =IF(COUNTIFS(Daten[myth_id],4,Daten[Zielgruppe],selectedGroup,Daten[Bevölkerungsrelevanz Pkt.],"<>")=0,"",SUMIFS(Daten[Bevölkerungsrelevanz Pkt.],Daten[myth_id],4,Daten[Zielgruppe],selectedGroup)) -> 11.2 | J5: =IF(klassFilter="Alle",1,IF($D5=klassFilter,1,0)) -> 1 | K5: =IF(katFilter="Alle",1,IF($C5=katFilter,1,0)) -> 1 | L5: =IF(LEN(sucheText)=0,1,IFERROR(IF(ISNUMBER(SEARCH(sucheText,$B5)),1,0),0)) -> 1 | M5: =$J5*$K5*$L5 -> 1 | N5: =CHOOSE(sortIdx,$A5,COUNTIF(Live!$B$2:$B$43,"<"&$B5)+1,COUNTIF(Live!$C$2:$C$43,"<"&$C5)+1,IFERROR(VLOOKUP($D5,Listen!$H$2:$I$6,2,FALSE()),99),$E5,$F5,$G5,$H5,$I5) -> 4 | O5: =IF($N5="",100000,sortDir*$N5)+ROW()*0.0001 -> 4.0005 | P5: =IF($M5<>1,0,COUNTIFS(Live!$M$2:$M$43,1,Live!$O$2:$O$43,"<"&$O5)+1) -> 4
A6: 5 | B6: Cannabis ist schwierig zu dosieren. | C6: Risiken durch Dosierung und Qualität | D6: Richtig | E6: =IF(COUNTIFS(Daten[myth_id],5,Daten[Zielgruppe],selectedGroup,Daten[Kenntnis %],"<>")=0,"",SUMIFS(Daten[Kenntnis %],Daten[myth_id],5,Daten[Zielgruppe],selectedGroup)) -> 16.33 | F6: =IF(COUNTIFS(Daten[myth_id],5,Daten[Zielgruppe],selectedGroup,Daten[Bedeutung Pkt.],"<>")=0,"",SUMIFS(Daten[Bedeutung Pkt.],Daten[myth_id],5,Daten[Zielgruppe],selectedGroup)) -> 68.51 | G6: =IF(COUNTIFS(Daten[myth_id],5,Daten[Zielgruppe],selectedGroup,Daten[Richtigkeit Pkt.],"<>")=0,"",SUMIFS(Daten[Richtigkeit Pkt.],Daten[myth_id],5,Daten[Zielgruppe],selectedGroup)) -> 76.43 | H6: =IF(COUNTIFS(Daten[myth_id],5,Daten[Zielgruppe],selectedGroup,Daten[Präventionsbedeutung Pkt.],"<>")=0,"",SUMIFS(Daten[Präventionsbedeutung Pkt.],Daten[myth_id],5,Daten[Zielgruppe],selectedGroup)) -> 26.37 | I6: =IF(COUNTIFS(Daten[myth_id],5,Daten[Zielgruppe],selectedGroup,Daten[Bevölkerungsrelevanz Pkt.],"<>")=0,"",SUMIFS(Daten[Bevölkerungsrelevanz Pkt.],Daten[myth_id],5,Daten[Zielgruppe],selectedGroup)) -> 5.1 | J6: =IF(klassFilter="Alle",1,IF($D6=klassFilter,1,0)) -> 1 | K6: =IF(katFilter="Alle",1,IF($C6=katFilter,1,0)) -> 1 | L6: =IF(LEN(sucheText)=0,1,IFERROR(IF(ISNUMBER(SEARCH(sucheText,$B6)),1,0),0)) -> 1 | M6: =$J6*$K6*$L6 -> 1 | N6: =CHOOSE(sortIdx,$A6,COUNTIF(Live!$B$2:$B$43,"<"&$B6)+1,COUNTIF(Live!$C$2:$C$43,"<"&$C6)+1,IFERROR(VLOOKUP($D6,Listen!$H$2:$I$6,2,FALSE()),99),$E6,$F6,$G6,$H6,$I6) -> 5 | O6: =IF($N6="",100000,sortDir*$N6)+ROW()*0.0001 -> 5.0006 | P6: =IF($M6<>1,0,COUNTIFS(Live!$M$2:$M$43,1,Live!$O$2:$O$43,"<"&$O6)+1) -> 5
A7: 6 | B7: Mischkonsum von Cannabis mit anderen Substanzen ist besonders risikoreich. | C7: Risiken durch Dosierung und Qualität | D7: Richtig | E7: =IF(COUNTIFS(Daten[myth_id],6,Daten[Zielgruppe],selectedGroup,Daten[Kenntnis %],"<>")=0,"",SUMIFS(Daten[Kenntnis %],Daten[myth_id],6,Daten[Zielgruppe],selectedGroup)) -> 43.75 | F7: =IF(COUNTIFS(Daten[myth_id],6,Daten[Zielgruppe],selectedGroup,Daten[Bedeutung Pkt.],"<>")=0,"",SUMIFS(Daten[Bedeutung Pkt.],Daten[myth_id],6,Daten[Zielgruppe],selectedGroup)) -> 77.02 | G7: =IF(COUNTIFS(Daten[myth_id],6,Daten[Zielgruppe],selectedGroup,Daten[Richtigkeit Pkt.],"<>")=0,"",SUMIFS(Daten[Richtigkeit Pkt.],Daten[myth_id],6,Daten[Zielgruppe],selectedGroup)) -> 88.97 | H7: =IF(COUNTIFS(Daten[myth_id],6,Daten[Zielgruppe],selectedGroup,Daten[Präventionsbedeutung Pkt.],"<>")=0,"",SUMIFS(Daten[Präventionsbedeutung Pkt.],Daten[myth_id],6,Daten[Zielgruppe],selectedGroup)) -> 21.93 | I7: =IF(COUNTIFS(Daten[myth_id],6,Daten[Zielgruppe],selectedGroup,Daten[Bevölkerungsrelevanz Pkt.],"<>")=0,"",SUMIFS(Daten[Bevölkerungsrelevanz Pkt.],Daten[myth_id],6,Daten[Zielgruppe],selectedGroup)) -> 11.7 | J7: =IF(klassFilter="Alle",1,IF($D7=klassFilter,1,0)) -> 1 | K7: =IF(katFilter="Alle",1,IF($C7=katFilter,1,0)) -> 1 | L7: =IF(LEN(sucheText)=0,1,IFERROR(IF(ISNUMBER(SEARCH(sucheText,$B7)),1,0),0)) -> 1 | M7: =$J7*$K7*$L7 -> 1 | N7: =CHOOSE(sortIdx,$A7,COUNTIF(Live!$B$2:$B$43,"<"&$B7)+1,COUNTIF(Live!$C$2:$C$43,"<"&$C7)+1,IFERROR(VLOOKUP($D7,Listen!$H$2:$I$6,2,FALSE()),99),$E7,$F7,$G7,$H7,$I7) -> 6 | O7: =IF($N7="",100000,sortDir*$N7)+ROW()*0.0001 -> 6.0007 | P7: =IF($M7<>1,0,COUNTIFS(Live!$M$2:$M$43,1,Live!$O$2:$O$43,"<"&$O7)+1) -> 6
A8: 7 | B8: Zusätze im Cannabis führen zu erhöhten Gesundheitsrisiken. | C8: Risiken durch Dosierung und Qualität | D8: Richtig | E8: =IF(COUNTIFS(Daten[myth_id],7,Daten[Zielgruppe],selectedGroup,Daten[Kenntnis %],"<>")=0,"",SUMIFS(Daten[Kenntnis %],Daten[myth_id],7,Daten[Zielgruppe],selectedGroup)) -> 35.06 | F8: =IF(COUNTIFS(Daten[myth_id],7,Daten[Zielgruppe],selectedGroup,Daten[Bedeutung Pkt.],"<>")=0,"",SUMIFS(Daten[Bedeutung Pkt.],Daten[myth_id],7,Daten[Zielgruppe],selectedGroup)) -> 76.49 | G8: =IF(COUNTIFS(Daten[myth_id],7,Daten[Zielgruppe],selectedGroup,Daten[Richtigkeit Pkt.],"<>")=0,"",SUMIFS(Daten[Richtigkeit Pkt.],Daten[myth_id],7,Daten[Zielgruppe],selectedGroup)) -> 85.7 | H8: =IF(COUNTIFS(Daten[myth_id],7,Daten[Zielgruppe],selectedGroup,Daten[Präventionsbedeutung Pkt.],"<>")=0,"",SUMIFS(Daten[Präventionsbedeutung Pkt.],Daten[myth_id],7,Daten[Zielgruppe],selectedGroup)) -> 24.05 | I8: =IF(COUNTIFS(Daten[myth_id],7,Daten[Zielgruppe],selectedGroup,Daten[Bevölkerungsrelevanz Pkt.],"<>")=0,"",SUMIFS(Daten[Bevölkerungsrelevanz Pkt.],Daten[myth_id],7,Daten[Zielgruppe],selectedGroup)) -> 10.1 | J8: =IF(klassFilter="Alle",1,IF($D8=klassFilter,1,0)) -> 1 | K8: =IF(katFilter="Alle",1,IF($C8=katFilter,1,0)) -> 1 | L8: =IF(LEN(sucheText)=0,1,IFERROR(IF(ISNUMBER(SEARCH(sucheText,$B8)),1,0),0)) -> 1 | M8: =$J8*$K8*$L8 -> 1 | N8: =CHOOSE(sortIdx,$A8,COUNTIF(Live!$B$2:$B$43,"<"&$B8)+1,COUNTIF(Live!$C$2:$C$43,"<"&$C8)+1,IFERROR(VLOOKUP($D8,Listen!$H$2:$I$6,2,FALSE()),99),$E8,$F8,$G8,$H8,$I8) -> 7 | O8: =IF($N8="",100000,sortDir*$N8)+ROW()*0.0001 -> 7.0008 | P8: =IF($M8<>1,0,COUNTIFS(Live!$M$2:$M$43,1,Live!$O$2:$O$43,"<"&$O8)+1) -> 7
A9: 8 | B9: Cannabiskonsum schädigt den Fötus. | C9: Risiken für den Körper und die Entwicklung | D9: Richtig | E9: =IF(COUNTIFS(Daten[myth_id],8,Daten[Zielgruppe],selectedGroup,Daten[Kenntnis %],"<>")=0,"",SUMIFS(Daten[Kenntnis %],Daten[myth_id],8,Daten[Zielgruppe],selectedGroup)) -> 42.35 | F9: =IF(COUNTIFS(Daten[myth_id],8,Daten[Zielgruppe],selectedGroup,Daten[Bedeutung Pkt.],"<>")=0,"",SUMIFS(Daten[Bedeutung Pkt.],Daten[myth_id],8,Daten[Zielgruppe],selectedGroup)) -> 76.49 | G9: =IF(COUNTIFS(Daten[myth_id],8,Daten[Zielgruppe],selectedGroup,Daten[Richtigkeit Pkt.],"<>")=0,"",SUMIFS(Daten[Richtigkeit Pkt.],Daten[myth_id],8,Daten[Zielgruppe],selectedGroup)) -> 89.87 | H9: =IF(COUNTIFS(Daten[myth_id],8,Daten[Zielgruppe],selectedGroup,Daten[Präventionsbedeutung Pkt.],"<>")=0,"",SUMIFS(Daten[Präventionsbedeutung Pkt.],Daten[myth_id],8,Daten[Zielgruppe],selectedGroup)) -> 21.16 | I9: =IF(COUNTIFS(Daten[myth_id],8,Daten[Zielgruppe],selectedGroup,Daten[Bevölkerungsrelevanz Pkt.],"<>")=0,"",SUMIFS(Daten[Bevölkerungsrelevanz Pkt.],Daten[myth_id],8,Daten[Zielgruppe],selectedGroup)) -> 11 | J9: =IF(klassFilter="Alle",1,IF($D9=klassFilter,1,0)) -> 1 | K9: =IF(katFilter="Alle",1,IF($C9=katFilter,1,0)) -> 1 | L9: =IF(LEN(sucheText)=0,1,IFERROR(IF(ISNUMBER(SEARCH(sucheText,$B9)),1,0),0)) -> 1 | M9: =$J9*$K9*$L9 -> 1 | N9: =CHOOSE(sortIdx,$A9,COUNTIF(Live!$B$2:$B$43,"<"&$B9)+1,COUNTIF(Live!$C$2:$C$43,"<"&$C9)+1,IFERROR(VLOOKUP($D9,Listen!$H$2:$I$6,2,FALSE()),99),$E9,$F9,$G9,$H9,$I9) -> 8 | O9: =IF($N9="",100000,sortDir*$N9)+ROW()*0.0001 -> 8.0009 | P9: =IF($M9<>1,0,COUNTIFS(Live!$M$2:$M$43,1,Live!$O$2:$O$43,"<"&$O9)+1) -> 8
A10: 9 | B10: Eine Überdosierung von Cannabis führt nicht zum Tod. | C10: Risiken durch Dosierung und Qualität | D10: Richtig | E10: =IF(COUNTIFS(Daten[myth_id],9,Daten[Zielgruppe],selectedGroup,Daten[Kenntnis %],"<>")=0,"",SUMIFS(Daten[Kenntnis %],Daten[myth_id],9,Daten[Zielgruppe],selectedGroup)) -> 20.71 | F10: =IF(COUNTIFS(Daten[myth_id],9,Daten[Zielgruppe],selectedGroup,Daten[Bedeutung Pkt.],"<>")=0,"",SUMIFS(Daten[Bedeutung Pkt.],Daten[myth_id],9,Daten[Zielgruppe],selectedGroup)) -> 66.53 | G10: =IF(COUNTIFS(Daten[myth_id],9,Daten[Zielgruppe],selectedGroup,Daten[Richtigkeit Pkt.],"<>")=0,"",SUMIFS(Daten[Richtigkeit Pkt.],Daten[myth_id],9,Daten[Zielgruppe],selectedGroup)) -> 74.3 | H10: =IF(COUNTIFS(Daten[myth_id],9,Daten[Zielgruppe],selectedGroup,Daten[Präventionsbedeutung Pkt.],"<>")=0,"",SUMIFS(Daten[Präventionsbedeutung Pkt.],Daten[myth_id],9,Daten[Zielgruppe],selectedGroup)) -> 27.58 | I10: =IF(COUNTIFS(Daten[myth_id],9,Daten[Zielgruppe],selectedGroup,Daten[Bevölkerungsrelevanz Pkt.],"<>")=0,"",SUMIFS(Daten[Bevölkerungsrelevanz Pkt.],Daten[myth_id],9,Daten[Zielgruppe],selectedGroup)) -> 6.6 | J10: =IF(klassFilter="Alle",1,IF($D10=klassFilter,1,0)) -> 1 | K10: =IF(katFilter="Alle",1,IF($C10=katFilter,1,0)) -> 1 | L10: =IF(LEN(sucheText)=0,1,IFERROR(IF(ISNUMBER(SEARCH(sucheText,$B10)),1,0),0)) -> 1 | M10: =$J10*$K10*$L10 -> 1 | N10: =CHOOSE(sortIdx,$A10,COUNTIF(Live!$B$2:$B$43,"<"&$B10)+1,COUNTIF(Live!$C$2:$C$43,"<"&$C10)+1,IFERROR(VLOOKUP($D10,Listen!$H$2:$I$6,2,FALSE()),99),$E10,$F10,$G10,$H10,$I10) -> 9 | O10: =IF($N10="",100000,sortDir*$N10)+ROW()*0.0001 -> 9.001 | P10: =IF($M10<>1,0,COUNTIFS(Live!$M$2:$M$43,1,Live!$O$2:$O$43,"<"&$O10)+1) -> 9
A11: 10 | B11: Cannabis wirkt gegen Schmerzen. | C11: Medizinischer und therapeutischer Nutzen | D11: Eher falsch | E11: =IF(COUNTIFS(Daten[myth_id],10,Daten[Zielgruppe],selectedGroup,Daten[Kenntnis %],"<>")=0,"",SUMIFS(Daten[Kenntnis %],Daten[myth_id],10,Daten[Zielgruppe],selectedGroup)) -> 68.28 | F11: =IF(COUNTIFS(Daten[myth_id],10,Daten[Zielgruppe],selectedGroup,Daten[Bedeutung Pkt.],"<>")=0,"",SUMIFS(Daten[Bedeutung Pkt.],Daten[myth_id],10,Daten[Zielgruppe],selectedGroup)) -> 70.26 | G11: =IF(COUNTIFS(Daten[myth_id],10,Daten[Zielgruppe],selectedGroup,Daten[Richtigkeit Pkt.],"<>")=0,"",SUMIFS(Daten[Richtigkeit Pkt.],Daten[myth_id],10,Daten[Zielgruppe],selectedGroup)) -> 49.74 | H11: =IF(COUNTIFS(Daten[myth_id],10,Daten[Zielgruppe],selectedGroup,Daten[Präventionsbedeutung Pkt.],"<>")=0,"",SUMIFS(Daten[Präventionsbedeutung Pkt.],Daten[myth_id],10,Daten[Zielgruppe],selectedGroup)) -> 46.58 | I11: =IF(COUNTIFS(Daten[myth_id],10,Daten[Zielgruppe],selectedGroup,Daten[Bevölkerungsrelevanz Pkt.],"<>")=0,"",SUMIFS(Daten[Bevölkerungsrelevanz Pkt.],Daten[myth_id],10,Daten[Zielgruppe],selectedGroup)) -> 34.1 | J11: =IF(klassFilter="Alle",1,IF($D11=klassFilter,1,0)) -> 1 | K11: =IF(katFilter="Alle",1,IF($C11=katFilter,1,0)) -> 1 | L11: =IF(LEN(sucheText)=0,1,IFERROR(IF(ISNUMBER(SEARCH(sucheText,$B11)),1,0),0)) -> 1 | M11: =$J11*$K11*$L11 -> 1 | N11: =CHOOSE(sortIdx,$A11,COUNTIF(Live!$B$2:$B$43,"<"&$B11)+1,COUNTIF(Live!$C$2:$C$43,"<"&$C11)+1,IFERROR(VLOOKUP($D11,Listen!$H$2:$I$6,2,FALSE()),99),$E11,$F11,$G11,$H11,$I11) -> 10 | O11: =IF($N11="",100000,sortDir*$N11)+ROW()*0.0001 -> 10.0011 | P11: =IF($M11<>1,0,COUNTIFS(Live!$M$2:$M$43,1,Live!$O$2:$O$43,"<"&$O11)+1) -> 10
